[2018-08-23 16:27:22,398: WARNING/ForkPoolWorker-3] __init__() takes at most 4 positional arguments (5 given)
[2018-08-23 16:30:04,388: ERROR/ForkPoolWorker-3] Task home.tasks.process_doc[0c08b2eb-64c2-4b9a-b10c-56bcc4e30175] raised unexpected: ConnectionError(MaxRetryError("HTTPSConnectionPool(host='web-beta.archive.org', port=443): Max retries exceeded with url: /save/http://iskme.org/media/in_the_news/one-example-nonprofit-moving-scale-through-collaborative-network (Caused by NewConnectionError('<urllib3.connection.VerifiedHTTPSConnection object at 0x7f8c35b14be0>: Failed to establish a new connection: [Errno -2] Name or service not known',))",),)
Traceback (most recent call last):
  File "/home/osboxes/.local/lib/python3.6/site-packages/urllib3/connection.py", line 141, in _new_conn
    (self.host, self.port), self.timeout, **extra_kw)
  File "/home/osboxes/.local/lib/python3.6/site-packages/urllib3/util/connection.py", line 60, in create_connection
    for res in socket.getaddrinfo(host, port, family, socket.SOCK_STREAM):
  File "/usr/lib/python3.6/socket.py", line 745, in getaddrinfo
    for res in _socket.getaddrinfo(host, port, family, type, proto, flags):
socket.gaierror: [Errno -2] Name or service not known

During handling of the above exception, another exception occurred:

Traceback (most recent call last):
  File "/home/osboxes/.local/lib/python3.6/site-packages/urllib3/connectionpool.py", line 601, in urlopen
    chunked=chunked)
  File "/home/osboxes/.local/lib/python3.6/site-packages/urllib3/connectionpool.py", line 346, in _make_request
    self._validate_conn(conn)
  File "/home/osboxes/.local/lib/python3.6/site-packages/urllib3/connectionpool.py", line 850, in _validate_conn
    conn.connect()
  File "/home/osboxes/.local/lib/python3.6/site-packages/urllib3/connection.py", line 284, in connect
    conn = self._new_conn()
  File "/home/osboxes/.local/lib/python3.6/site-packages/urllib3/connection.py", line 150, in _new_conn
    self, "Failed to establish a new connection: %s" % e)
urllib3.exceptions.NewConnectionError: <urllib3.connection.VerifiedHTTPSConnection object at 0x7f8c35b14be0>: Failed to establish a new connection: [Errno -2] Name or service not known

During handling of the above exception, another exception occurred:

Traceback (most recent call last):
  File "/home/osboxes/.local/lib/python3.6/site-packages/requests/adapters.py", line 440, in send
    timeout=timeout
  File "/home/osboxes/.local/lib/python3.6/site-packages/urllib3/connectionpool.py", line 639, in urlopen
    _stacktrace=sys.exc_info()[2])
  File "/home/osboxes/.local/lib/python3.6/site-packages/urllib3/util/retry.py", line 388, in increment
    raise MaxRetryError(_pool, url, error or ResponseError(cause))
urllib3.exceptions.MaxRetryError: HTTPSConnectionPool(host='web-beta.archive.org', port=443): Max retries exceeded with url: /save/http://iskme.org/media/in_the_news/one-example-nonprofit-moving-scale-through-collaborative-network (Caused by NewConnectionError('<urllib3.connection.VerifiedHTTPSConnection object at 0x7f8c35b14be0>: Failed to establish a new connection: [Errno -2] Name or service not known',))

During handling of the above exception, another exception occurred:

Traceback (most recent call last):
  File "/home/osboxes/.local/lib/python3.6/site-packages/celery/app/trace.py", line 382, in trace_task
    R = retval = fun(*args, **kwargs)
  File "/home/osboxes/.local/lib/python3.6/site-packages/celery/app/trace.py", line 641, in __protected_call__
    return self.run(*args, **kwargs)
  File "/home/osboxes/Documents/Work/SPN2_with_Google_Sheet_Web/home/tasks.py", line 48, in process_doc
    job_id = request_capture(url, headers)
  File "/home/osboxes/Documents/Work/SPN2_with_Google_Sheet_Web/home/tasks.py", line 80, in request_capture
    response = requests.get(url=SPN_URL + url, headers=headers)
  File "/home/osboxes/.local/lib/python3.6/site-packages/requests/api.py", line 72, in get
    return request('get', url, params=params, **kwargs)
  File "/home/osboxes/.local/lib/python3.6/site-packages/requests/api.py", line 58, in request
    return session.request(method=method, url=url, **kwargs)
  File "/home/osboxes/.local/lib/python3.6/site-packages/requests/sessions.py", line 508, in request
    resp = self.send(prep, **send_kwargs)
  File "/home/osboxes/.local/lib/python3.6/site-packages/requests/sessions.py", line 618, in send
    r = adapter.send(request, **kwargs)
  File "/home/osboxes/.local/lib/python3.6/site-packages/requests/adapters.py", line 508, in send
    raise ConnectionError(e, request=request)
requests.exceptions.ConnectionError: HTTPSConnectionPool(host='web-beta.archive.org', port=443): Max retries exceeded with url: /save/http://iskme.org/media/in_the_news/one-example-nonprofit-moving-scale-through-collaborative-network (Caused by NewConnectionError('<urllib3.connection.VerifiedHTTPSConnection object at 0x7f8c35b14be0>: Failed to establish a new connection: [Errno -2] Name or service not known',))
[2018-08-23 16:34:53,205: WARNING/ForkPoolWorker-3] __init__() takes at most 4 positional arguments (5 given)
[2018-08-23 16:56:21,619: WARNING/ForkPoolWorker-3] __init__() takes at most 4 positional arguments (5 given)
[2018-08-23 17:27:05,777: WARNING/ForkPoolWorker-3] __init__() takes at most 4 positional arguments (5 given)
[2018-08-23 17:42:08,808: WARNING/ForkPoolWorker-3] __init__() takes at most 4 positional arguments (5 given)
